---
title: deferでのエラー処理
tags:
  - Go
private: true
updated_at: '2024-09-02T21:22:11+09:00'
id: 684331bd23e563be981a
organization_url_name: null
slide: false
ignorePublish: false
---
# deferでのエラー処理

次の例は、顧客IDを指定してデータベースに問い合わせ、残高を取得する関数を実装します。database/sqlパッケージとQueryメソッドを使う。

```go
const query = "..."

func getBalance1(db *sql.DB, clientID string) (float32, error) {
	rows, err := db.Query(query, clientID)
	if err != nil {
		return 0, err
	}
	defer rows.Close()

	// Use rows
	return 0, nil
}
```

rowsは`*sql.Rows`型でCloserインターフェイスを実装している。

```go
type Closer interface {
    Close() error
}
```

このインターフェイスには、エラーを返すCloseメソッドが1つ含まれてる。エラーは常に処理されるべきであるが、この場合、deferに与えた呼び出しによって返されたエラーは無視される。

```go
defer rows.Close()
```

エラーを無視したい場合は、ブランク識別子を使用する。

```go
defer func() { _ = rows.Close() } ()
```

これは冗長だが、エラーを無視していることを明示しているので、保守性の観点からは優れている。

deferに与えられた呼び出しによる全てのエラーを闇雲に無視するのではなく、無視するのが最善の方法か否かを自問すべきである。この場合、コネクションプールからDBコネクションを開放することは、行いたいことではなく、最善の選択はメッセージをログに記録すること。

```go
defer func() {
    err := rows.Close()
    if err != nil {
        log.Printf("failed to close rows: %v", err)
    }
}()
```

これで、行のクローズに失敗した時に、コードはメッセージをログに記録し、それを認識できる。このエラー処理をする代わりに、getBalanceの呼び出し元にそのエラーを伝え、呼び出し元がそのエラーの処理方法を決められるようにすると

```go
defer func() {
    err := rows.Close()
    if err != nil {
        return err
    }
}()
```

これはコンパイルできない。return文はgetBalanceではなく、無名のfunc()関数と関連づけられている。

もし、getBalanceが返すエラーをdeferに与えた呼び出しで捕らえたエラーと結びつけたければ、名前付き結果パラメータを使う必要がある。

```go
func getBalance3(db *sql.DB, clientID string) (balance float32, err error) {
	rows, err := db.Query(query, clientID)
	if err != nil {
		return 0, err
	}
    defer func() {
        err := rows.Close() 
    }()
    if rows.Next() {
        err := rows.Scan(&balance)
        if err != nil {
            return 0, err
        }
        return balance, nil
    }
	return balance, nil
    }
    // 省略
}
```


無名関数の最終的な実装は以下のようになる。

```go
func getBalance3(db *sql.DB, clientID string) (balance float32, err error) {
	rows, err := db.Query(query, clientID)
	if err != nil {
		return 0, err
	}
	defer func() {
		closeErr := rows.Close()
		if err != nil {
			if closeErr != nil {
				log.Printf("failed to close rows: %v", closeErr)
			}
			return
		}
		err = closeErr
	}()

	// Use rows
	return 0, nil
}
```
